2022-11-20 15:41:30,283 - instabot version: 0.117.0 (bot) - INFO - Instabot version: 0.117.0 Started
2022-11-20 15:41:30,284 - instabot version: 0.117.0 (bot) - DEBUG - Bot imported from C:\Users\user\Desktop\InstaBot\venv\lib\site-packages\instabot\bot\bot.py
2022-11-20 15:41:30,285 - instabot version: 0.117.0 (api_login) - INFO - Not yet logged in starting: PRE-LOGIN FLOW!
2022-11-20 15:41:30,299 - instabot version: 0.117.0 (api) - WARNING - HTTPSConnectionPool(host='i.instagram.com', port=443): Max retries exceeded with url: /api/v1/accounts/get_prefill_candidates/ (Caused by NewConnectionError('<urllib3.connection.HTTPSConnection object at 0x0000022A9F1D58D0>: Failed to establish a new connection: [Errno 11001] getaddrinfo failed'))
2022-11-20 15:41:30,437 - instabot version: 0.117.0 (api) - WARNING - HTTPSConnectionPool(host='i.instagram.com', port=443): Max retries exceeded with url: /api/v1/qe/sync/ (Caused by NewConnectionError('<urllib3.connection.HTTPSConnection object at 0x0000022A9F1D58A0>: Failed to establish a new connection: [Errno 11001] getaddrinfo failed'))
2022-11-20 15:41:30,440 - instabot version: 0.117.0 (api) - WARNING - HTTPSConnectionPool(host='i.instagram.com', port=443): Max retries exceeded with url: /api/v1/launcher/sync/ (Caused by NewConnectionError('<urllib3.connection.HTTPSConnection object at 0x0000022A9F1D5870>: Failed to establish a new connection: [Errno 11001] getaddrinfo failed'))
2022-11-20 15:41:30,445 - instabot version: 0.117.0 (api) - WARNING - HTTPSConnectionPool(host='i.instagram.com', port=443): Max retries exceeded with url: /api/v1/accounts/contact_point_prefill/ (Caused by NewConnectionError('<urllib3.connection.HTTPSConnection object at 0x0000022A9F1D4EE0>: Failed to establish a new connection: [Errno 11001] getaddrinfo failed'))
