2022-11-20 17:55:49,175 - instabot version: 0.117.0 (bot) - INFO - Instabot version: 0.117.0 Started
2022-11-20 17:55:49,175 - instabot version: 0.117.0 (bot) - DEBUG - Bot imported from C:\Users\user\Desktop\InstaBot\venv\lib\site-packages\instabot\bot\bot.py
2022-11-20 17:55:49,176 - instabot version: 0.117.0 (api_login) - INFO - Not yet logged in starting: PRE-LOGIN FLOW!
2022-11-20 17:55:49,213 - instabot version: 0.117.0 (api) - WARNING - HTTPSConnectionPool(host='i.instagram.com', port=443): Max retries exceeded with url: /api/v1/accounts/get_prefill_candidates/ (Caused by NewConnectionError('<urllib3.connection.HTTPSConnection object at 0x00000294B00FCC10>: Failed to establish a new connection: [Errno 11001] getaddrinfo failed'))
2022-11-20 17:55:49,217 - instabot version: 0.117.0 (api) - WARNING - HTTPSConnectionPool(host='i.instagram.com', port=443): Max retries exceeded with url: /api/v1/qe/sync/ (Caused by NewConnectionError('<urllib3.connection.HTTPSConnection object at 0x00000294B00FCC70>: Failed to establish a new connection: [Errno 11001] getaddrinfo failed'))
2022-11-20 17:55:49,220 - instabot version: 0.117.0 (api) - WARNING - HTTPSConnectionPool(host='i.instagram.com', port=443): Max retries exceeded with url: /api/v1/launcher/sync/ (Caused by NewConnectionError('<urllib3.connection.HTTPSConnection object at 0x00000294B00FCB80>: Failed to establish a new connection: [Errno 11001] getaddrinfo failed'))
2022-11-20 17:55:49,226 - instabot version: 0.117.0 (api) - WARNING - HTTPSConnectionPool(host='i.instagram.com', port=443): Max retries exceeded with url: /api/v1/accounts/contact_point_prefill/ (Caused by NewConnectionError('<urllib3.connection.HTTPSConnection object at 0x00000294B00FCBE0>: Failed to establish a new connection: [Errno 11001] getaddrinfo failed'))
