2022-11-20 17:53:29,384 - instabot version: 0.117.0 (bot) - INFO - Instabot version: 0.117.0 Started
2022-11-20 17:53:29,385 - instabot version: 0.117.0 (bot) - DEBUG - Bot imported from C:\Users\user\Desktop\InstaBot\venv\lib\site-packages\instabot\bot\bot.py
2022-11-20 17:53:29,386 - instabot version: 0.117.0 (api_login) - INFO - Not yet logged in starting: PRE-LOGIN FLOW!
2022-11-20 17:53:29,398 - instabot version: 0.117.0 (api) - WARNING - HTTPSConnectionPool(host='i.instagram.com', port=443): Max retries exceeded with url: /api/v1/accounts/get_prefill_candidates/ (Caused by NewConnectionError('<urllib3.connection.HTTPSConnection object at 0x000001A8762A59F0>: Failed to establish a new connection: [Errno 11001] getaddrinfo failed'))
2022-11-20 17:53:29,403 - instabot version: 0.117.0 (api) - WARNING - HTTPSConnectionPool(host='i.instagram.com', port=443): Max retries exceeded with url: /api/v1/qe/sync/ (Caused by NewConnectionError('<urllib3.connection.HTTPSConnection object at 0x000001A8762A58D0>: Failed to establish a new connection: [Errno 11001] getaddrinfo failed'))
2022-11-20 17:53:29,407 - instabot version: 0.117.0 (api) - WARNING - HTTPSConnectionPool(host='i.instagram.com', port=443): Max retries exceeded with url: /api/v1/launcher/sync/ (Caused by NewConnectionError('<urllib3.connection.HTTPSConnection object at 0x000001A8762A5A20>: Failed to establish a new connection: [Errno 11001] getaddrinfo failed'))
2022-11-20 17:53:29,415 - instabot version: 0.117.0 (api) - WARNING - HTTPSConnectionPool(host='i.instagram.com', port=443): Max retries exceeded with url: /api/v1/accounts/contact_point_prefill/ (Caused by NewConnectionError('<urllib3.connection.HTTPSConnection object at 0x000001A8762A59F0>: Failed to establish a new connection: [Errno 11001] getaddrinfo failed'))
